<?xml version="1.0" ?>
<robot name="urdf_oven">
  <link name="root">
  </link>
  <joint name="root_rotation" type="fixed">
    <origin rpy="0 0 0" xyz="0 0 0"/>
    <parent link="root"/>
    <child link="body"/>
  </joint>
  <link name="body">
    <inertial>
      <origin rpy="0 0 0" xyz="0 0 0"/>
      <mass value="70.0"/>
      <inertia ixx="1.0" ixy="0" ixz="0" iyy="1.0" iyz="0" izz="1.0"/>
    </inertial>
    <visual>
      <origin rpy="0 0 0" xyz="0 0 0"/>
      <geometry>
        <mesh filename="kitchen_oven_base.glb" scale="1.0, 1.0, 1.0"/>
      </geometry>
    </visual>
    <collision group="2">
      <origin rpy="0 0 0" xyz="0 0 0"/>
      <geometry>
        <mesh filename="kitchen_oven_base_COLLISION.glb" scale="1.0, 1.0, 1.0"/>
      </geometry>
    </collision>
  </link>
  <joint name="top_door_hinge" type="revolute">
    <origin rpy="0 0 0" xyz="0.000284 0.229124 -0.629578"/>
    <parent link="body"/>
    <child link="top_door"/>
    <axis xyz="-1 0 0"/>
    <dynamics damping="0.01" friction="0.01"/>
    <limit effort="44.4" lower="0.0" upper="1.6" velocity="40"/>
  </joint>
  <link name="top_door">
    <inertial>
      <origin rpy="0 0 0" xyz="0 0 0"/>
      <mass value="8"/>
      <inertia ixx="1.0" ixy="0" ixz="0" iyy="1.0" iyz="0" izz="1.0"/>
    </inertial>
    <visual>
      <origin rpy="0 0 0" xyz="0 0 0"/>
      <geometry>
        <mesh filename="kitchen_oven_door.glb" scale="1.0, 1.0, 1.0"/>
      </geometry>
    </visual>
    <collision group="4">
      <origin rpy="0 0 0" xyz="0 0 0"/>
      <geometry>
        <mesh filename="kitchen_oven_door.glb" scale="1.0, 1.0, 1.0"/>
      </geometry>
    </collision>
  </link>
</robot>
